Workbook

Sheet Product Orientation
A1: Company Name | B1: TTK HEALTHCARE LTD | K1: Home | L1: Next Step >
A2: Innovator/Generic | B2: Innovator
A3: Brand Name | B3: VIRILEX
A4: Drug Class
C7: Ingredients | H7: Doses & Duration of Treatment
C8: Add details of main ingredients | H8: Provide details of typical dosage and duration of treatment, by clicking on the sub heading link
H10: =CONCATENATE(C101," ",D101," for ",I103," ",J103,"."," Total treatment cost is ",E103," ",ROUND(F103,0)," (",E101," ",ROUND(F101,0)," ",H101," or ",E102," ",ROUND(F102,0)," ",H102) -> 3 per day for 45 days. Total treatment cost is INR 3602 (INR 80 per day or INR 2401 per month
C12: Use | H12: MRP
C13: Describe use of the drug | H13: Provide MRP of drug
C16: Key Ingredient | D16: (Name) | H16: Other Ingredients
C17: (Mechanism of Action)
C19: Pack | H19: Last Year Sales
C20: =A106&" "&B106&" and "&A107&" "&B107 -> 10 tabs and 20 tabs | H20: Enter previous year sales
A100: < Back | C100: Dosage | F100: Cost to user
A101: Per Day | C101: 3 | D101: per day | E101: =E102 -> INR | F101: =E106*C101 -> 80.043 | H101: per day
A102: How many months? | B102: 1.5 | C102: =(B102*30)*C101 -> 135 | D102: tablets | E102: =E103 -> INR | F102: =(C102/B102)*E106 -> 2401.29 | H102: per month
A103: How many years? | B103: 0 | C103: =B103*365*C101 -> 0 | D103: tablets | E103: =D106 -> INR | F103: =C102*E106 -> 3601.935 | H103: Total | I103: =B102*30 -> 45 | J103: days
A105: Pack type | C105: MRP
A106: 10 | B106: tabs | C106: 266.81 | D106: INR | E106: =C106/A106 -> 26.681
A107: 20 | B107: tabs | C107: 577 | D107: INR | E107: =C107/A107 -> 28.85

Sheet Environment Understanding
A1: Environmental Understanding
A2: Macro | B2: Population of India | C2: =ROUND((B58/10^9),2)&" Bn ("&ROUND((((B58-C58)/C58)*100),1)&"%)" -> 1.44 Bn (0.7%) | D2: Urban | E2: =D58 -> 0.368 | F2: Rural | G2: =E58 -> 0.632 | H2: Disease Burden | I2: High | J2: Is the country attractive to do business in? | AA2: =D59 -> Yes | AB2: {=_xlfn.IFS(E2<30%,"Low",E2<60%,"Medium",E2>60%,"High")} -> Medium | AC2: =I2 -> High | AE2: =IF(AA2="Yes",1,0) -> 1 | AF2: {=_xlfn.IFS(AB2="Low",0,AB2="Medium",0.5,AB2="High",1)} -> 0.5 | AG2: {=_xlfn.IFS(AC2="Low to none",0,AC2="moderate",0.5,AC2="High",1)} -> 1
B3: GDP (GR%) | C3: ="$"&F58&" Tr ("&ROUND(((F58-G58)/G58)*100,1)&"%)" -> $27.36 Tr (7.3%) | D3: GNI per Capita | E3: =H58 -> 8230 | AA3: =D59 -> Yes | AB3: =H60 -> No | AE3: =IF(AA3="Yes",1,0) -> 1 | AF3: =IF(AB3="Yes",1,0) -> 0 | AI3: =SUM(AE2:AG5) -> 7
B4: IP (Patent) | C4: Strong | D4: Reimbursed | E4: Out of Pocket | F4: Private Insurance | G4: >30% | AA4: =C4 -> Strong | AB4: =E4 -> Out of Pocket | AC4: =G4 -> >30% | AE4: {=_xlfn.IFS(AA4="Weak",0,AA4="moderate",0.5,AA4="Strong",1)} -> 1 | AF4: {=_xlfn.IFS(AB4="out of pocket",0,AB4="partial",0.5,AB4="full",1)} -> 0 | AG4: {=_xlfn.IFS(AC4="<30%",0,AC4=30%,0.5,AC4=">30%",1)} -> 1
B5: Indian Pharma Market | C5: ="$"&I58&" Bn ("&TEXT(J58,"0.0%")&")" -> $54.6 Bn (12.3%) | D5: Innovator vs Generic | E5: Balanced | J5: {=_xlfn.IFS(AI3>=6.5,"Yes",AI3<=6.5,"Moderate",AI3<5,"No")} -> Yes | AA5: =J60 -> Yes | AB5: {=_xlfn.IFS(E5="Innovators Dominate","Innovator",E5="Generics Dominate","Generic",E5="Balanced","Balanced")} -> Balanced | AC5: ='Product Orientation'!B2 -> Innovator | AE5: =IF(AA5="Yes",1,0) -> 1 | AF5: =IF(AB5="Balanced",0.5,IF(AB5=AC5,1,0)) -> 0.5
A6: Market | B6: Market Attractiveness | J6: Is the industry attractive to do business in?
B7: Category Size | C7: Moderate | D7: Regulatory Challenges | E7: Low to none
B8: Category Growth | C8: Low to none | D8: Product Life cycle | E8: High
B9: Competitive Intensity | C9: Low to none | J9: {=_xlfn.IFS((COUNTIF(C7:E9,"High")*5)+(COUNTIF(C7:E9,"MODERATE")*3)+COUNTIF(C7:E9,"LOW TO NONE")<12,"No",(COUNTIF(C7:E9,"High")*5)+(COUNTIF(C7:E9,"MODERATE")*3)+COUNTIF(C7:E9,"LOW TO NONE")>18,"Yes",(COUNTIF(C7:E9,"High")*5)+(COUNTIF(C7:E9,"MODERATE")*3)+COUNTIF(C7:E9,"LOW TO NONE")>12,"Moderate")} -> No
A10: Represented Market | B10: Market Size & Growth | C10: =ROUND('Top Brand'!J19,1)&" Cr "&TEXT('Top Brand'!T34,"0%")&"GR" -> 139.3 Cr 8%GR | F10: Key Brands, Market Share & Growth | G10: ='Contested Cat.'!P37&CHAR(10)&'Contested Cat.'!P38&CHAR(10)&'Contested Cat.'!P39 -> TENTEX FORTE (HIMALAYA) ~25Cr ~7% GR ~18% MS CONFIDO (HIMALAYA) ~21Cr ~4% GR ~15% MS ADDYZOA (CHARAK) ~13Cr ~6% GR ~9% MS | J10: Is the represented market attractive to do business in? | AA10: {=_xlfn.IFS('AWACS input'!D3>500,"Medium",'AWACS input'!D3>1000,"High",'AWACS input'!D3<500,"Low")} -> Low | AB10: =IF('AWACS input'!D4>'Environment Understanding'!J58,"Yes","No") -> No | AE10: {=_xlfn.IFS(AA10="High",5,AA10="Medium",3,AA10="Low",1)} -> 1 | AF10: =IF(AB10="Yes",1,0) -> 0 | AH10: =SUM(AE10:AF11) -> 7
B11: Key Players, Market Share & Growth | C11: ='Top Brand'!L45&CHAR(10)&'Top Brand'!L46&CHAR(10)&'Top Brand'!L47 -> HIMALAYA ~63.4Cr ~2%GR ~45%MS CHARAK ~20.2Cr ~5%GR ~15%MS SANZYME ~9.6Cr ~33%GR ~7%MS | AA11: {=_xlfn.IFS(D13="monopoly",0,D13="Oligopoly",1,D13="Fragmented",3)} -> 1 | AB11: {=_xlfn.IFS(G13="policy has brand name",5,G13="policy has molecule",3,G13="No policy",1,G13="policy favours other molecule",0)} -> 5 | AE11: =AA11 -> 1 | AF11: =AB11 -> 5
F12: Total No. of Brands | G12: ='Contested Cat.'!P11 -> ~42 Brands
B13: Total No. of Companies | C13: ='AWACS input'!D6 -> 27 | D13: ='Top Brand'!I49 -> Oligopoly | F13: Influence of National Policies | G13: Policy has Brand Name | J13: {=_xlfn.IFS(AH10>8,"Yes",AH10>6,"Moderate",AH10<6,"No")} -> Moderate
A14: Competing Capability | B14: Clinical Evidence/Endorsements | D14: Product Design-Uniqueness/Superiority | F14: Business Strength | J14: Is the brand attractive to do business?
B15: Publication | C15: Moderate | D15: Ingredient | E15: High | F15: Product Strength | G15: High
B16: Patents | C16: Moderate | D16: Claims | E16: High | F16: Manufacturing & Development Capability | G16: High
B17: Trials | C17: High | D17: Delivery Technology | E17: High | F17: Channel Strength | G17: High
B18: Medical Societies | C18: High | D18: Format | E18: High | J18: {=_xlfn.IFS((COUNTIF(C15:G19,"High")*5)+(COUNTIF(C15:G19,"MODERATE")*3)+COUNTIF(C15:G19,"LOW TO NONE")<22,"No",(COUNTIF(C15:G19,"High")*5)+(COUNTIF(C15:G19,"MODERATE")*3)+COUNTIF(C15:G19,"LOW TO NONE")>44,"Yes",(COUNTIF(C15:G19,"High")*5)+(COUNTIF(C15:G19,"MODERATE")*3)+COUNTIF(C15:G19,"LOW TO NONE")>22,"Moderate")} -> Yes
B20: * The above data has been taken as of April 2024 | H20: < Previous Step | I20: Home | J20: Next Step >
B55: < Back
A56: Macro
A57: Country | B57: Population 2024 | C57: Population 2023 | D57: Urban 2024 | E57: Rural 2024 | F57: GDP 2023 ($ Tr) | G57: GDP 2022 ($ Tr) | H57: GNI per capita | I57: Pharma market size 2023 (Bn) | J57: GR | K57: Ease of Business Index 2023 | L57: Private Hospitals | M57: Public Hospitals | N57: IP (Patent) | O57: Reimbursed | P57: Private Insurance | Q57: IP (Patent)
A58: India | B58: 1439240390 | C58: 1428675850 | D58: 0.368 | E58: =100%-D58 -> 0.632 | F58: 27.36 | G58: 25.5 | H58: 8230 | I58: 54.6 | J58: 0.123 | K58: 0.744
A59: China | B59: -0.0001 | C59: =(B58-C58)/C58 -> 0.0073946375 | D59: =IF(C59>B59,"Yes","No") -> Yes | F59: =(F58-G58)/G58 -> 0.072941176 | G59: =IF(F59>6%,"Yes","No") -> Yes | H59: 21250 | I59: 246 | J59: 0.084
H60: =IF(H58>H59,"Yes","No") -> No | J60: =IF(J58>J59,"Yes","No") -> Yes

Sheet Market Definition
A1: Market Definition
B2: Data | C2: Definition
A3: Market Definition | B3: ='AWACS input'!B9 -> SEX TONICS & STIMULANTS | V3X2 | C3: Market definition can also be described as category definition e.g. Type 2 Diabetes oral market/Acid peptic disorder, choice is to be made by what you feel that product, molecule from the same or different class compete with one another
A4: Market Size | B4: ="~"&ROUND('AWACS input'!D3,0)&" Cr Growth Rate "&TEXT('AWACS input'!D4,"0%") -> ~139 Cr Growth Rate 8% | C4: What is the size (AWACS) Growth MAT XXX
A5: Molecule, Drug Class | B5: ='Product Orientation'!D16 -> (Name) | C5: • Key molecules and drug classes
A6: Physician Universe | B6: =CONCATENATE(Segmentation!A2,CHAR(10),Segmentation!A3,CHAR(10),Segmentation!A4) -> Cardiologist | C6: • Which are the top most specialities in the market in terms of total prescriptions as welll as PD ration
A7: Patient Universe | B7: ='Patient Funnel'!D2*10^6 -> 2000000000 | C7: What is the actual universe of patients living with disease mentioned
A8: Key Players [Brands, Company, Market Share] | B8: ="#1 "&'Contested Cat.'!P37&CHAR(10)&"#2 "&'Contested Cat.'!P38&CHAR(10)&"#3 "&'Contested Cat.'!P39 -> #1 TENTEX FORTE (HIMALAYA) ~25Cr ~7% GR ~18% MS #2 CONFIDO (HIMALAYA) ~21Cr ~4% GR ~15% MS #3 ADDYZOA (CHARAK) ~13Cr ~6% GR ~9% MS | C8: • What are the main brands and their companies

Sheet Patient Funnel
A1: Filter Level | B1: Description | D1: Nos. (in Mn) | E1: %
A2: 1 | B2: No. of patients living with the disease | D2: 2000
A3: 2 | B3: No. of patients diagnosed with the disease | C3: =($D$2-D3)/2 -> 200 | D3: =D2*E3 -> 1600 | E3: 0.8
A4: 3 | B4: No. of Patients treated | C4: =($D$2-D4)/2 -> 440 | D4: =D3*E4 -> 1120 | E4: 0.7
A5: 4 | B5: Target Patients | C5: =($D$2-D5)/2 -> 720 | D5: =D4*E5 -> 560 | E5: 0.5
S6: \

Sheet Patient Journey Mapping
B1: Patient Journey Map
A2: Disease burden & no. of patients living with defined disease No. or % of patients appear to HCPs with compelling symptoms or reasons | B2: Origination
A4: No. of patients diagnosed by HCPs deploying certain type of tests | B4: Diagnosis
A6: No. or % of patients are given specific treatment No. or % of patients are given specific treatment Treatment choices made as 1st line 2nd line | B6: Treatment & Class Choices | E6: AWACS Data, surgical, pharma, other - then check classes
A8: No. or % of patients receiving choice brand vs. other brands | B8: Brand Choice
A10: No. or % of pharmacies honoring and patient buying No. or % of patients adhering to choice brand | B10: Access
C12: Make input areas for diagnosis types, and treament+Class choice

Sheet Leverage Point
C1: Y/N | D1: Leakage %
A2: Market Expansion | B2: Origination | C2: N | D2: 0.9 | Y2: =IF(L8="NO","NO",IF(C2="Y","YES",C2)) -> N
B3: Diagnosis | C3: N | D3: 0.5 | Y3: =IF(L9="NO","NO",IF(C3="Y","YES",C3)) -> N
B4: Treatment Choice | C4: Y | D4: 0.5 | Y4: =IF(L10="NO","NO",IF(C4="Y","YES",C4)) -> YES
A5: Share Penetration | B5: Class Choice | C5: N | D5: 0.25 | Y5: =IF(L10="No",IF(Y6="Yes","No","Yes"),IF(C5="Y","YES",C5)) -> N
B6: Brand Choice | C6: Y | D6: 0.5 | Y6: =IF(L10="NO",IF(D6<45%,"Yes","No"),IF(C6="Y","YES",C6)) -> YES
A7: Share Expansion | B7: Fulfilment | C7: N | D7: 0.9 | Y7: =IF(L10="NO",IF(Y6="Yes","Yes","No"),IF(C7="Y","YES",C7)) -> N
B8: Adherence | C8: N | D8: 0.6 | Y8: =IF(L10="NO",IF(Y6="Yes","Yes","No"),IF(C8="Y","YES",C8)) -> N
A10: Qualitative approach to identify your leverage point from patients' journey mapping | K10: User Option | L10: Yes
A11: #1 | B11: Can we distinctively identify the biggest bottle necks?
A12: #2 | B12: What is the current behaviour? Can we change this behaviour? | J12: if brand choice is below 45 then brand choice, full and adherace
A13: #3 | B13: Would that desired behaviour drive significant volume for class/franchise? | J13: If above 50, then class choice
A14: #4 | B14: Would it disproportionately drive prescription for our product vs competition? | J14: Give option for user choice also, max 3
A15: #5 | B15: Would driving this behaviour be achieved at the desired cost?

Sheet KSH
B1: Type | C1: % Influence | D1: Drivers & Barriers | E1: Drivers & Barriers
A2: Patients | B2: Infertile Women | C2: 0.2 | AA2: =MAX(100%,C2)-C2 -> 0.8
A3: Professionals | B3: Gynecologists | C3: 0.2 | AA3: =MAX(100%,C3)-C3 -> 0.8
A4: Providers/Hospitals | B4: Pharmacies | C4: 0.25 | AA4: =MAX(100%,C4)-C4 -> 0.75
A5: Payer/Self-Pay Families | B5: Insurance | C5: 0.25 | AA5: =MAX(100%,C5)-C5 -> 0.75
A6: Policy Makers | B6: Government | C6: 0.1 | AA6: =MAX(100%,C6)-C6 -> 0.9
C7: =SUM(C2:C6) -> 1

Sheet Contested Cat.
C3: Write take away here
D8: Segment | P8: Category
P9: ="~"&ROUND('AWACS input'!D3,0)&" Cr market GR "&TEXT('AWACS input'!D4,"0%") -> ~139 Cr market GR 8%
P10: =TEXT('AWACS input'!D2,"0%")&" CAGR over last "&'AWACS input'!E2&" years" -> 4% CAGR over last 5 years
P11: ="~"&'AWACS input'!D5&" Brands" -> ~42 Brands | W11: input for reach and physician reach
E13: doctor
E14: and
E15: coverage
O37: #1 | P37: ='Top Brand'!B8&" ("&_xlfn.TEXTBEFORE('Top Brand'!C8," ",1,,1)&") "&"~"&ROUND('Top Brand'!J8,0)&"Cr ~"&TEXT('Top Brand'!T25,"0%")&" GR ~"&TEXT('Top Brand'!K8,"0%")&" MS" -> TENTEX FORTE (HIMALAYA) ~25Cr ~7% GR ~18% MS | W37: =_xlfn.TEXTBEFORE(P37,"~") -> TENTEX FORTE (HIMALAYA)
O38: #2 | P38: ='Top Brand'!B9&" ("&_xlfn.TEXTBEFORE('Top Brand'!C9," ",1,,1)&") "&"~"&ROUND('Top Brand'!J9,0)&"Cr ~"&TEXT('Top Brand'!T26,"0%")&" GR ~"&TEXT('Top Brand'!K9,"0%")&" MS" -> CONFIDO (HIMALAYA) ~21Cr ~4% GR ~15% MS | W38: =_xlfn.TEXTBEFORE(P38,"~") -> CONFIDO (HIMALAYA)
O39: #3 | P39: ='Top Brand'!B10&" ("&_xlfn.TEXTBEFORE('Top Brand'!C10," ",1,,1)&") "&"~"&ROUND('Top Brand'!J10,0)&"Cr ~"&TEXT('Top Brand'!T27,"0%")&" GR ~"&TEXT('Top Brand'!K10,"0%")&" MS" -> ADDYZOA (CHARAK) ~13Cr ~6% GR ~9% MS | W39: =_xlfn.TEXTBEFORE(P39,"~") -> ADDYZOA (CHARAK)
O41: Brand | P41: ='Top Brand'!B6&" ("&_xlfn.TEXTBEFORE('Top Brand'!C6," ",1,,1)&") "&"~"&ROUND('Top Brand'!J6,0)&"Cr ~"&TEXT('Top Brand'!T33,"0%")&" growth ~"&TEXT('Top Brand'!K6,"0%")&" MS" -> VIRILEX (TTK) ~6Cr ~18% growth ~5% MS | W41: =_xlfn.TEXTBEFORE(P41,"~") -> VIRILEX (TTK)

Sheet Brand Wheel
C2: Features & Attributes | E2: Product Design 1 | K2: Supporting Evidence | Q2: Rational Benefits | S2: Patients 1
E3: Product Design 2 | S3: Patients 2 | AP3: =IF(F12="",C12,F12) -> Single Minded Proposition
E4: Product Design 3 | S4: Customers 1 | AP4: =IF(M7="",K7,M7) -> Key Customer Insight
E5: Clinical Data 1 | S5: Customers 2 | AP5: =IF(F13="",C13,F13) -> Brand essence
E6: Clinical Data 2
E7: Clinical Data 3 | K7: Key Customer Insight | Q7: Emotional Benefits | S7: Patients 1
E8: Endorsements 1 | S8: Patients 2
E9: Endorsements 2 | S9: Customers 1
E10: Endorsements 3 | S10: Customers 2
C12: Single Minded Proposition
C13: Brand essence
C16: Features & Attributes | Q16: Rational Benefits
C19: Product Design | Q19: Patients
C20: =IF(F2="","","- "&F2) | Q20: =IF(T2="","","- "&T2)
C21: =IF(F3="","","- "&F3) | Q21: =IF(T3="","","- "&T3)
C22: =IF(F4="","","- "&F4)
Q23: Customers
C24: Clinical Data | Q24: =IF(T4="","","- "&T4)
C25: =IF(F5="","","- "&F5) | Q25: =IF(T5="","","- "&T5)
C26: =IF(F6="","","- "&F6)
C27: =IF(F7="","","- "&F7)
C29: Endorsements
C30: =IF(F8="","","- "&F8)
C31: =IF(F9="","","- "&F9)
C32: =IF(F10="","","- "&F10)
C37: Supporting Evidence | Q37: Emotional Benefits
C40: =IF(M2="","","- "&M2) | Q40: Patients
Q41: =IF(T7="","","- "&T7)
Q42: =IF(T8="","","- "&T8)
Q44: Customers
Q45: =IF(T9="","","- "&T9)
Q46: =IF(T10="","","- "&T10)

Sheet Segmentation
A1: Select HCP | C1: Universe | D1: Coverage | E1: MMM % | F1: Tier 1 % | G1: Tier 2% | H1: Tier 3% | I1: Tier 4 & Below % | J1: MMM | K1: Tier 1 | L1: Tier 2 | M1: Tier 3 | N1: Tier 4 & Below
A2: Cardiologist | B2: HPL | C2: =IF(A2="","",_xlfn.XLOOKUP(A2,Tools!$A$2:$A$29,Tools!$B$2:$B$29)) -> 0 | J2: =IF(E2="","",$C2*E2) | K2: =IF(F2="","",$C2*F2) | L2: =IF(G2="","",$C2*G2) | M2: =IF(H2="","",$C2*H2) | N2: =IF(I2="","",$C2*I2)
B3: MPL | C3: =IF(A3="","",_xlfn.XLOOKUP(A3,Tools!$A$2:$A$29,Tools!$B$2:$B$29)) | J3: =IF(E3="","",$C3*E3) | K3: =IF(F3="","",$C3*F3) | L3: =IF(G3="","",$C3*G3) | M3: =IF(H3="","",$C3*H3) | N3: =IF(I3="","",$C3*I3)
B4: LPL | C4: =IF(A4="","",_xlfn.XLOOKUP(A4,Tools!$A$2:$A$29,Tools!$B$2:$B$29)) | J4: =IF(E4="","",$C4*E4) | K4: =IF(F4="","",$C4*F4) | L4: =IF(G4="","",$C4*G4) | M4: =IF(H4="","",$C4*H4) | N4: =IF(I4="","",$C4*I4)
A5: Not on List | J5: =IF(E5="","",$C5*E5) | K5: =IF(F5="","",$C5*F5) | L5: =IF(G5="","",$C5*G5) | M5: =IF(H5="","",$C5*H5) | N5: =IF(I5="","",$C5*I5)
E8: =IF(A2="","",IF(SUM(E2:I2)<>100%,"Total for row 2 needs to be 100%","")) -> Total for row 2 needs to be 100%
E9: =IF(A3="","",IF(SUM(E3:I3)<>100%,"Total for row 3 needs to be 100%",""))
E10: =IF(A4="","",IF(SUM(E4:I4)<>100%,"Total for row 4 needs to be 100%",""))
E11: =IF(SUM(E5:I5)=0,"",IF(SUM(E5:I5)<>100%,"Total for row 5 needs to be 100%",""))

Sheet SWOT
C5: Market Attractiveness Opportunities & Threats | L5: Competing Capabilities Strenghts & Weakness
T9: Pull data from relevant sources
D10: Market | M10: Market Share
M11: ='Contested Cat.'!P41 -> VIRILEX (TTK) ~6Cr ~18% growth ~5% MS
D18: Competitive Intensity | M18: Value Proposition or Differentiation
M19: =IF('Brand Wheel'!F12="","",'Brand Wheel'!F12)
D26: Customer/Consumer Engagements | M26: Customer/Consumer Engagements
D27: Comp data | M27: Comp data
T29: Comp data section
D37: - Market Size, Growth | M37: - Brand Share & growth
D38: - Patient universe, diagnosed & treated pool | M38: - Product design, clinical data or endorsements as key differentiator
D39: - Competitive Intensity # of players, top 3 leaders | M39: - Brand's value proposition, support program e.g. access
D40: - Customer/Consumer Engagement of key competitors FF size, key strength | M40: - Customer consumer engagement and FF size

Sheet Top Brand
B1: No. of Top Brands | C1: 10
B2: Home
A5: MAT VAL (in Crs.)
B6: ='Product Orientation'!B3 -> VIRILEX | C6: =_xlfn.XLOOKUP($B$6,'AWACS input'!$C$9:$C$66,'AWACS input'!D9:D66) -> TTK HEALTHCARE LTD | D6: =_xlfn.XLOOKUP($B$6,'AWACS input'!$C$9:$C$66,'AWACS input'!E9:E66) -> VIRILEX TABLET 20 | E6: =_xlfn.XLOOKUP($B$6,'AWACS input'!$C$9:$C$66,'AWACS input'!F9:F66) -> 375 | F6: =_xlfn.XLOOKUP($B$6,'AWACS input'!$C$9:$C$66,'AWACS input'!G9:G66) -> 5.6440445 | G6: =_xlfn.XLOOKUP($B$6,'AWACS input'!$C$9:$C$66,'AWACS input'!H9:H66) -> 5.5517663 | H6: =_xlfn.XLOOKUP($B$6,'AWACS input'!$C$9:$C$66,'AWACS input'!I9:I66) -> 5.3500679 | I6: =_xlfn.XLOOKUP($B$6,'AWACS input'!$C$9:$C$66,'AWACS input'!J9:J66) -> 5.3306099 | J6: =_xlfn.XLOOKUP($B$6,'AWACS input'!$C$9:$C$66,'AWACS input'!K9:K66) -> 6.2840625 | K6: =IF(J6="","",J6/$J$19) -> 0.045110489
B7: {=_xlfn._xlws.SORT(_xlfn._xlws.FILTER('AWACS input'!$C$8:$K$500,'AWACS input'!$K$8:$K$500>=LARGE('AWACS input'!$K$8:$K$500,'Top Brand'!$C$1)),9,-1)} -> BRAND | C7: COMPANY | D7: SKU | E7: PTR | F7: Sum of MAT VAL DEC 17 | G7: Sum of MAT VAL DEC 18 | H7: Sum of MAT VAL DEC 19 | I7: Sum of MAT VAL DEC 20 | J7: Sum of MAT VAL DEC 21 | K7: % | O7: Brand | P7: =RIGHT(F7,6) -> DEC 17 | Q7: =RIGHT(G7,6) -> DEC 18 | R7: =RIGHT(H7,6) -> DEC 19 | S7: =RIGHT(I7,6) -> DEC 20 | T7: =RIGHT(J7,6) -> DEC 21
A8: {=_xlfn.SEQUENCE(C1)} -> 1 | B8: TENTEX FORTE | C8: HIMALAYA DRUG COMPANY | D8: TENTEX FORTE TABLET 10 | E8: 55 | F8: 15.467838 | G8: 19.924983 | H8: 21.996633 | I8: 23.650366 | J8: 25.389485 | K8: =IF(J8="","",J8/$J$19) -> 0.18225982 | O8: =B8 -> TENTEX FORTE | P8: =F8 -> 15.467838 | Q8: =G8 -> 19.924983 | R8: =H8 -> 21.996633 | S8: =I8 -> 23.650366 | T8: =J8 -> 25.389485
A9: 2 | B9: CONFIDO | C9: HIMALAYA DRUG COMPANY | D9: CONFIDO TABLET 60 | E9: 96.24 | F9: 15.63728 | G9: 18.031377 | H9: 18.09849 | I9: 20.386765 | J9: 21.17662 | K9: =IF(J9="","",J9/$J$19) -> 0.15201754 | O9: =B9 -> CONFIDO | P9: =F9 -> 15.63728 | Q9: =G9 -> 18.031377 | R9: =H9 -> 18.09849 | S9: =I9 -> 20.386765 | T9: =J9 -> 21.17662
A10: 3 | B10: ADDYZOA | C10: CHARAK PHARMA PVT LTD | D10: ADDYZOA CAPSULE 20 | E10: 132.13 | F10: 10.837602 | G10: 11.946439 | H10: 11.564507 | I10: 12.296885 | J10: 13.049718 | K10: =IF(J10="","",J10/$J$19) -> 0.093678121 | O10: =B10 -> ADDYZOA | P10: =F10 -> 10.837602 | Q10: =G10 -> 11.946439 | R10: =H10 -> 11.564507 | S10: =I10 -> 12.296885 | T10: =J10 -> 13.049718
A11: 4 | B11: HIMCOLIN | C11: HIMALAYA DRUG COMPANY | D11: HIMCOLIN GEL 30 GM | E11: 120.31 | F11: 6.3444094 | G11: 10.231342 | H11: 12.178191 | I11: 10.320915 | J11: 9.6567242 | K11: =IF(J11="","",J11/$J$19) -> 0.069321327 | O11: =B11 -> HIMCOLIN | P11: =F11 -> 6.3444094 | Q11: =G11 -> 10.231342 | R11: =H11 -> 12.178191 | S11: =I11 -> 10.320915 | T11: =J11 -> 9.6567242
A12: 5 | B12: SIOTONE | C12: ALBERT DAVID | D12: SIOTONE CAPSULE 10 | E12: 117.14 | F12: 8.9375234 | G12: 8.32464 | H12: 8.236171 | I12: 6.394069 | J12: 7.7516612 | K12: =IF(J12="","",J12/$J$19) -> 0.055645727 | O12: =B12 -> SIOTONE | P12: =F12 -> 8.9375234 | Q12: =G12 -> 8.32464 | R12: =H12 -> 8.236171 | S12: =I12 -> 6.394069 | T12: =J12 -> 7.7516612
A13: 6 | B13: ENDOBLOC T | C13: CIPLA LTD. | D13: ENDOBLOC T KIT TABLET 10 | E13: 1359.6 | F13: 1.7859071 | G13: 3.8063685 | H13: 4.7201856 | I13: 6.3375272 | J13: 7.3298755 | K13: =IF(J13="","",J13/$J$19) -> 0.052617915
A14: 7 | B14: SPEMAN | C14: HIMALAYA DRUG COMPANY | D14: SPEMAN TABLET 60 | E14: 99.69 | F14: 8.9340506 | G14: 8.960424 | H14: 8.5660266 | I14: 8.0282692 | J14: 7.1490788 | K14: =IF(J14="","",J14/$J$19) -> 0.051320056
A15: 8 | B15: NANO LEO | C15: SANZYME LTD | D15: NANO LEO CAPSULE 15 | E15: 508.47 | F15: 5.1178064 | G15: 5.9034374 | H15: 6.209049 | I15: 4.4764274 | J15: 7.0084846 | K15: =IF(J15="","",J15/$J$19) -> 0.050310793
A16: 9 | B16: VIRILEX | C16: TTK HEALTHCARE LTD | D16: VIRILEX TABLET 20 | E16: 375 | F16: 5.6440445 | G16: 5.5517663 | H16: 5.3500679 | I16: 5.3306099 | J16: 6.2840625 | K16: =IF(J16="","",J16/$J$19) -> 0.045110489 | O16: Brand | P16: =F6 -> 5.6440445 | Q16: =G6 -> 5.5517663 | R16: =H6 -> 5.3500679 | S16: =I6 -> 5.3306099 | T16: =J6 -> 6.2840625
A17: 10 | B17: ERACT X | C17: ZYDUS CADILA - ZHL | D17: ERACT X SACHET 10 GM | E17: 62.24 | F17: 0 | G17: 1.5142289 | H17: 5.6595108 | I17: 5.6511347 | J17: 6.0488706 | K17: =IF(J17="","",J17/$J$19) -> 0.043422151 | O17: =A19 -> T | P17: =F19 -> 116.50501 | Q17: =G19 -> 128.72314 | R17: =H19 -> 136.04218 | S17: =I19 -> 129.27016 | T17: =J19 -> 139.3038
A19: T | F19: =_xlfn.XLOOKUP(F7,'AWACS input'!$8:$8,'AWACS input'!$7:$7) -> 116.50501 | G19: =_xlfn.XLOOKUP(G7,'AWACS input'!$8:$8,'AWACS input'!$7:$7) -> 128.72314 | H19: =_xlfn.XLOOKUP(H7,'AWACS input'!$8:$8,'AWACS input'!$7:$7) -> 136.04218 | I19: =_xlfn.XLOOKUP(I7,'AWACS input'!$8:$8,'AWACS input'!$7:$7) -> 129.27016 | J19: =_xlfn.XLOOKUP(J7,'AWACS input'!$8:$8,'AWACS input'!$7:$7) -> 139.3038
A23: MAT UNIT (in Crs.)
B24: =B6 -> VIRILEX | O24: Brand | Q24: =Q7 -> DEC 18 | R24: =R7 -> DEC 19 | S24: =S7 -> DEC 20 | T24: =T7 -> DEC 21
B25: {=_xlfn._xlws.SORT(_xlfn._xlws.FILTER(_xlfn._xlws.FILTER('AWACS input'!$C$8:$P$500,'AWACS input'!$P$8:$P$500>=LARGE('AWACS input'!$P$8:$P$500,'Top Brand'!$C$1)),{1,1,1,0,0,0,0,0,0,1,1,1,1,1}),8,-1)} -> BRAND | C25: COMPANY | D25: SKU | E25: Sum of MAT UNIT DEC 17 | F25: Sum of MAT UNIT DEC 18 | G25: Sum of MAT UNIT DEC 19 | H25: Sum of MAT UNIT DEC 20 | I25: Sum of MAT UNIT DEC 21 | K25: % | O25: =O8 -> TENTEX FORTE | Q25: =(Q8-P8)/P8 -> 0.28815566 | R25: =(R8-Q8)/Q8 -> 0.10397244 | S25: =(S8-R8)/R8 -> 0.07518119 | T25: =(T8-S8)/S8 -> 0.073534586
A26: {=_xlfn.SEQUENCE(C1)} -> 1 | B26: TENTEX FORTE | C26: HIMALAYA DRUG COMPANY | D26: TENTEX FORTE TABLET 10 | E26: 3847.717 | F26: 4786.984 | G26: 4922.048 | H26: 4981.354 | I26: 4786.463 | K26: =IF(I26="","",I26/$I$37) -> 0.34421202 | O26: =O9 -> CONFIDO | Q26: =(Q9-P9)/P9 -> 0.15310191 | R26: =(R9-Q9)/Q9 -> 0.0037219866 | S26: =(S9-R9)/R9 -> 0.12643457 | T26: =(T9-S9)/S9 -> 0.038743553
A27: 2 | B27: CONFIDO | C27: HIMALAYA DRUG COMPANY | D27: CONFIDO TABLET 60 | E27: 2106.101 | F27: 2384.472 | G27: 2208.768 | H27: 2280.909 | I27: 2233.203 | K27: =IF(I27="","",I27/$I$37) -> 0.16059778 | O27: =O10 -> ADDYZOA | Q27: =(Q10-P10)/P10 -> 0.10231388 | R27: =(R10-Q10)/Q10 -> -0.031970359 | S27: =(S10-R10)/R10 -> 0.063329773 | T27: =(T10-S10)/S10 -> 0.061221494
A28: 3 | B28: ADDYZOA | C28: CHARAK PHARMA PVT LTD | D28: ADDYZOA CAPSULE 20 | E28: 987.267 | F28: 1063.121 | G28: 971.048 | H28: 994.235 | I28: 1006.264 | K28: =IF(I28="","",I28/$I$37) -> 0.072364117 | O28: =O11 -> HIMCOLIN | Q28: =(Q11-P11)/P11 -> 0.61265473 | R28: =(R11-Q11)/Q11 -> 0.19028289 | S28: =(S11-R11)/R11 -> -0.15250837 | T28: =(T11-S11)/S11 -> -0.064353864
A29: 4 | B29: ERACT X | C29: ZYDUS CADILA - ZHL | D29: ERACT X SACHET 10 GM | E29: 0 | F29: 280.933 | G29: 1050.002 | H29: 1048.448 | I29: 991.467 | K29: =IF(I29="","",I29/$I$37) -> 0.07130001 | O29: =O12 -> SIOTONE | Q29: =(Q12-P12)/P12 -> -0.068574189 | R29: =(R12-Q12)/Q12 -> -0.010627366 | S29: =(S12-R12)/R12 -> -0.22366 | T29: =(T12-S12)/S12 -> 0.21232054
A30: 5 | B30: HIMCOLIN | C30: HIMALAYA DRUG COMPANY | D30: HIMCOLIN GEL 30 GM | E30: 665.234 | F30: 1063.107 | G30: 1188.086 | H30: 938.265 | I30: 821.656 | K30: =IF(I30="","",I30/$I$37) -> 0.059088282
A31: 6 | B31: SPEMAN | C31: HIMALAYA DRUG COMPANY | D31: SPEMAN TABLET 60 | E31: 1094.881 | F31: 1086.112 | G31: 996.861 | H31: 865.022 | I31: 735.431 | K31: =IF(I31="","",I31/$I$37) -> 0.052887527
A32: 7 | B32: SIOTONE | C32: ALBERT DAVID | D32: SIOTONE CAPSULE 10 | E32: 865.056 | F32: 832.464 | G32: 786.66 | H32: 581.279 | I32: 665.237 | K32: =IF(I32="","",I32/$I$37) -> 0.04783962
A33: 8 | B33: NEO | C33: CHARAK PHARMA PVT LTD | D33: NEO TABLET 75 | E33: 603.185 | F33: 625.205 | G33: 627.915 | H33: 574.183 | I33: 590.353 | K33: =IF(I33="","",I33/$I$37) -> 0.042454439 | O33: Brand | Q33: =(Q16-P16)/P16 -> -0.016349667 | R33: =(R16-Q16)/Q16 -> -0.036330489 | S33: =(S16-R16)/R16 -> -0.0036369604 | T33: =(T16-S16)/S16 -> 0.1788637
A34: 9 | B34: NANO LEO TOTAL | C34: SANZYME LTD | D34: NANO LEO TOTAL SACHET 3 GM | E34: 625.615 | F34: 713.165 | G34: 549.071 | H34: 365.851 | I34: 450.577 | K34: =IF(I34="","",I34/$I$37) -> 0.032402636 | O34: T | Q34: =(Q17-P17)/P17 -> 0.10487216 | R34: =(R17-Q17)/Q17 -> 0.056858811 | S34: =(S17-R17)/R17 -> -0.049778852 | T34: =(T17-S17)/S17 -> 0.077617594
A35: 10 | B35: SEMENTO | C35: AIMIL PHARMACEUTICAL (INDIA) | D35: SEMENTO CAPSULE 20 | E35: 0 | F35: 0 | G35: 97.345 | H35: 247.668 | I35: 239.452 | K35: =IF(I35="","",I35/$I$37) -> 0.017219867
A37: T | E37: =_xlfn.XLOOKUP(E25,'AWACS input'!$8:$8,'AWACS input'!$7:$7) -> 13509.862 | F37: =_xlfn.XLOOKUP(F25,'AWACS input'!$8:$8,'AWACS input'!$7:$7) -> 15218.667 | G37: =_xlfn.XLOOKUP(G25,'AWACS input'!$8:$8,'AWACS input'!$7:$7) -> 15416.961 | H37: =_xlfn.XLOOKUP(H25,'AWACS input'!$8:$8,'AWACS input'!$7:$7) -> 14219.935 | I37: =_xlfn.XLOOKUP(I25,'AWACS input'!$8:$8,'AWACS input'!$7:$7) -> 13905.566
B44: Row Labels | C44: Count of COMPANY | D44: Sum of Sum of MAT VAL DEC 20 | E44: Sum of Sum of MAT VAL DEC 21 | G44: =RIGHT(D44,10) -> VAL DEC 20 | H44: =RIGHT(E44,10) -> VAL DEC 21 | I44: GR | J44: MS
B45: HIMALAYA DRUG COMPANY | C45: 4 | D45: 62.386314 | E45: 63.371909 | F45: =B45 -> HIMALAYA DRUG COMPANY | G45: =GETPIVOTDATA("Sum of Sum of MAT VAL DEC 20",$B$44,"COMPANY",F45) -> 62.386314 | H45: =GETPIVOTDATA("Sum of Sum of MAT VAL DEC 21",$B$44,"COMPANY",F45) -> 63.371909 | I45: =(H45-G45)/H45 -> 0.015552544 | J45: =H45/$J$19 -> 0.45491874 | L45: =CONCATENATE(_xlfn.TEXTBEFORE(F45," ")," ~",ROUND(H45,1),"Cr ~",TEXT(I45,"0%"),"GR ~",TEXT(J45,"0%"),"MS") -> HIMALAYA ~63.4Cr ~2%GR ~45%MS
B46: CHARAK PHARMA PVT LTD | C46: 8 | D46: 19.160694 | E46: 20.202969 | F46: =B46 -> CHARAK PHARMA PVT LTD | G46: =GETPIVOTDATA("Sum of Sum of MAT VAL DEC 20",$B$44,"COMPANY",F46) -> 19.160694 | H46: =GETPIVOTDATA("Sum of Sum of MAT VAL DEC 21",$B$44,"COMPANY",F46) -> 20.202969 | I46: =(H46-G46)/H46 -> 0.051590184 | J46: =H46/$J$19 -> 0.14502813 | L46: =CONCATENATE(_xlfn.TEXTBEFORE(F46," ")," ~",ROUND(H46,1),"Cr ~",TEXT(I46,"0%"),"GR ~",TEXT(J46,"0%"),"MS") -> CHARAK ~20.2Cr ~5%GR ~15%MS
B47: SANZYME LTD | C47: 3 | D47: 6.4285078 | E47: 9.5847301 | F47: =B47 -> SANZYME LTD | G47: =GETPIVOTDATA("Sum of Sum of MAT VAL DEC 20",$B$44,"COMPANY",F47) -> 6.4285078 | H47: =GETPIVOTDATA("Sum of Sum of MAT VAL DEC 21",$B$44,"COMPANY",F47) -> 9.5847301 | I47: =(H47-G47)/H47 -> 0.32929694 | J47: =H47/$J$19 -> 0.068804513 | L47: =CONCATENATE(_xlfn.TEXTBEFORE(F47," ")," ~",ROUND(H47,1),"Cr ~",TEXT(I47,"0%"),"GR ~",TEXT(J47,"0%"),"MS") -> SANZYME ~9.6Cr ~33%GR ~7%MS
B48: ALBERT DAVID | C48: 1 | D48: 6.394069 | E48: 7.7516612
B49: CIPLA LTD. | C49: 1 | D49: 6.3375272 | E49: 7.3298755 | I49: {=_xlfn.IFS(J45>60%,"Monopoly",J49>65%,"Oligopoly",J49<65%,"Fragmented")} -> Oligopoly | J49: =SUM(J45:J48) -> 0.66875138
B50: ZYDUS CADILA - ZHL | C50: 3 | D50: 6.7651808 | E50: 7.0189128
B51: TTK HEALTHCARE LTD | C51: 4 | D51: 5.407012 | E51: 6.5596022
B52: AIMIL PHARMACEUTICAL (INDIA) | C52: 1 | D52: 4.017918 | E52: 4.1960721
B53: DABUR INDIA LTD. | C53: 6 | D53: 3.1625554 | E53: 3.7598094
...

Sheet AWACS input
G1: ="20"&RIGHT(G8,2) -> 2017 | H1: ="20"&RIGHT(H8,2) -> 2018 | I1: ="20"&RIGHT(I8,2) -> 2019 | J1: ="20"&RIGHT(J8,2) -> 2020 | K1: ="20"&RIGHT(K8,2) -> 2021
B2: ='Product Orientation'!B1 -> TTK HEALTHCARE LTD | C2: Market CAGR | D2: =((K7/G7)^(1/COUNT(G7:K7)))-1 -> 0.036391098 | E2: =COUNT(G9:K9) -> 5 | F2: Years
B3: ='Product Orientation'!B3 -> VIRILEX | C3: Market Size | D3: =K7 -> 139.3038 | E3: Cr | G3: =_xlfn.XLOOKUP($B$3,$C$9:$C$600,G9:G600) -> 5.6440445 | H3: =_xlfn.XLOOKUP($B$3,$C$9:$C$600,H9:H600) -> 5.5517663 | I3: =_xlfn.XLOOKUP($B$3,$C$9:$C$600,I9:I600) -> 5.3500679 | J3: =_xlfn.XLOOKUP($B$3,$C$9:$C$600,J9:J600) -> 5.3306099 | K3: =_xlfn.XLOOKUP($B$3,$C$9:$C$600,K9:K600) -> 6.2840625
C4: Growth Rate | D4: =(K7-J7)/J7 -> 0.077617594
C5: No. of Brands | D5: {=SUMPRODUCT(1/COUNTIF(C9:C66,C9:C66))} -> 42
C6: No. of Companies | D6: {=SUMPRODUCT(1/COUNTIF(D9:D66,D9:D66))} -> 27
B7: Insert AWACS data below & remove all totals | C7: =IFERROR(_xlfn.XMATCH("Total",A9:A500,0,1),0) -> 0 | E7: Totals | G7: =SUBTOTAL(9,G9:G998) -> 116.50501 | H7: =SUBTOTAL(9,H9:H998) -> 128.72314 | I7: =SUBTOTAL(9,I9:I998) -> 136.04218 | J7: =SUBTOTAL(9,J9:J998) -> 129.27016 | K7: =SUBTOTAL(9,K9:K998) -> 139.3038 | L7: =SUBTOTAL(9,L9:L998) -> 13509.862 | M7: =SUBTOTAL(9,M9:M998) -> 15218.667 | N7: =SUBTOTAL(9,N9:N998) -> 15416.961 | ... CK7: =SUBTOTAL(9,CK9:CK998) -> 1347316
B8: SUBGROUP | C8: BRAND | D8: COMPANY | E8: SKU | F8: PTR | G8: Sum of MAT VAL DEC 17 | H8: Sum of MAT VAL DEC 18 | I8: Sum of MAT VAL DEC 19 | J8: Sum of MAT VAL DEC 20 | K8: Sum of MAT VAL DEC 21 | L8: Sum of MAT UNIT DEC 17 | M8: Sum of MAT UNIT DEC 18 | N8: Sum of MAT UNIT DEC 19 | O8: Sum of MAT UNIT DEC 20 | P8: Sum of MAT UNIT DEC 21 | Q8: Column1 | R8: Sum of SALES VALUE JAN-19 | S8: Sum of SALES VALUE FEB-19 | T8: Sum of SALES VALUE MAR-19 | U8: Sum of SALES VALUE APR-19 | V8: Sum of SALES VALUE MAY-19 | W8: Sum of SALES VALUE JUN-19 | X8: Sum of SALES VALUE JUL-19 | Y8: Sum of SALES VALUE AUG-19 | Z8: Sum of SALES VALUE SEP-19 | AA8: Sum of SALES VALUE OCT-19 | AB8: Sum of SALES VALUE NOV-19 | AC8: Sum of SALES VALUE DEC-19 | AD8: Sum of SALES VALUE JAN-20 | AE8: Sum of SALES VALUE FEB-20 | AF8: Sum of SALES VALUE MAR-20 | AG8: Sum of SALES VALUE APR-20 | AH8: Sum of SALES VALUE MAY-20 | AI8: Sum of SALES VALUE JUN-20 | AJ8: Sum of SALES VALUE JUL-20 | AK8: Sum of SALES VALUE AUG-20 | AL8: Sum of SALES VALUE SEP-20 | AM8: Sum of SALES VALUE OCT-20 | AN8: Sum of SALES VALUE NOV-20 | AO8: Sum of SALES VALUE DEC-20 | AP8: Sum of SALES VALUE JAN-21 | AQ8: Sum of SALES VALUE FEB-21 | AR8: Sum of SALES VALUE MAR-21 | AS8: Sum of SALES VALUE APR-21 | AT8: Sum of SALES VALUE MAY-21 | AU8: Sum of SALES VALUE JUN-21 | AV8: Sum of SALES VALUE JUL-21 | AW8: Sum of SALES VALUE AUG-21 | AX8: Sum of SALES VALUE SEP-21 | AY8: Sum of SALES VALUE OCT-21 | AZ8: Sum of SALES VALUE NOV-21 | BA8: Sum of SALES VALUE DEC-21 | BB8: Sum of SALES UNIT JAN-19 | BC8: Sum of SALES UNIT FEB-19 | BD8: Sum of SALES UNIT MAR-19 | BE8: Sum of SALES UNIT APR-19 | BF8: Sum of SALES UNIT MAY-19 | BG8: Sum of SALES UNIT JUN-19 | BH8: Sum of SALES UNIT JUL-19 | BI8: Sum of SALES UNIT AUG-19 | BJ8: Sum of SALES UNIT SEP-19 | BK8: Sum of SALES UNIT OCT-19 | BL8: Sum of SALES UNIT NOV-19 | BM8: Sum of SALES UNIT DEC-19 | BN8: Sum of SALES UNIT JAN-20 | BO8: Sum of SALES UNIT FEB-20 | BP8: Sum of SALES UNIT MAR-20 | BQ8: Sum of SALES UNIT APR-20 | BR8: Sum of SALES UNIT MAY-20 | BS8: Sum of SALES UNIT JUN-20 | BT8: Sum of SALES UNIT JUL-20 | BU8: Sum of SALES UNIT AUG-20 | BV8: Sum of SALES UNIT SEP-20 | BW8: Sum of SALES UNIT OCT-20 | BX8: Sum of SALES UNIT NOV-20 | BY8: Sum of SALES UNIT DEC-20 | BZ8: Sum of SALES UNIT JAN-21 | CA8: Sum of SALES UNIT FEB-21 | CB8: Sum of SALES UNIT MAR-21 | CC8: Sum of SALES UNIT APR-21 | CD8: Sum of SALES UNIT MAY-21 | CE8: Sum of SALES UNIT JUN-21 | CF8: Sum of SALES UNIT JUL-21 | CG8: Sum of SALES UNIT AUG-21 | CH8: Sum of SALES UNIT SEP-21 | CI8: Sum of SALES UNIT OCT-21 | CJ8: Sum of SALES UNIT NOV-21 | CK8: Sum of SALES UNIT DEC-21
A9: =RIGHT(B9,5) -> V3X2 | B9: SEX TONICS & STIMULANTS | V3X2 | C9: TENTEX FORTE | D9: HIMALAYA DRUG COMPANY | E9: TENTEX FORTE TABLET 10 | F9: 55 | G9: 15.467838 | H9: 19.924983 | I9: 21.996633 | J9: 23.650366 | K9: 25.389485 | L9: 3847.717 | M9: 4786.984 | N9: 4922.048 | O9: 4981.354 | P9: 4786.463 | R9: 22715972 | S9: 20052492 | T9: 15807836 | U9: 15621121 | V9: 14714182 | W9: 13004164 | X9: 13860335 | Y9: 23283401 | Z9: 22796995 | AA9: 15280226 | AB9: 17043381 | AC9: 25786219 | AD9: 23223471 | AE9: 18458087 | AF9: 16742728 | AG9: 14638730 | AH9: 15778548 | AI9: 18363314 | AJ9: 25927297 | AK9: 20998798 | AL9: 18466146 | AM9: 17872105 | AN9: 15925218 | AO9: 30109213 | AP9: 24370518 | AQ9: 22533874 | AR9: 18565466 | AS9: 18529885 | AT9: 15318820 | AU9: 26278450 | AV9: 29635485 | AW9: 19733340 | AX9: 18119475 | AY9: 16004890 | AZ9: 14179055 | BA9: 30625595 | BB9: 508301 | BC9: 448702 | BD9: 353722 | BE9: 349544 | BF9: 329250 | BG9: 290986 | BH9: 310144 | BI9: 520998 | BJ9: 510114 | BK9: 341916 | BL9: 381369 | BM9: 577002 | BN9: 519657 | BO9: 413025 | BP9: 347937 | BQ9: 304213 | BR9: 327900 | BS9: 381615 | BT9: 538805 | BU9: 436384 | BV9: 383752 | BW9: 371407 | BX9: 330948 | BY9: 625711 | BZ9: 506453 | CA9: 468285 | CB9: 385816 | CC9: 336907 | CD9: 278524 | CE9: 477790 | CF9: 538827 | CG9: 358788 | CH9: 329445 | CI9: 290998 | CJ9: 257801 | CK9: 556829
A10: =RIGHT(B10,5) -> V3X2 | B10: SEX TONICS & STIMULANTS | V3X2 | C10: CONFIDO | D10: HIMALAYA DRUG COMPANY | E10: CONFIDO TABLET 60 | F10: 96.24 | G10: 15.63728 | H10: 18.031377 | I10: 18.09849 | J10: 20.386765 | K10: 21.17662 | L10: 2106.101 | M10: 2384.472 | N10: 2208.768 | O10: 2280.909 | P10: 2233.203 | R10: 13612281 | S10: 13897372 | T10: 15390540 | U10: 19264740 | V10: 16122728 | W10: 13648635 | X10: 14749020 | Y10: 14245110 | Z10: 14125898 | AA10: 13549388 | AB10: 16501485 | AC10: 15877702 | AD10: 19968207 | AE10: 26340465 | AF10: 17055045 | AG10: 12854721 | AH10: 13991545 | AI10: 14510128 | AJ10: 13943101 | AK10: 18178373 | AL10: 17562097 | AM10: 16041654 | AN10: 15973457 | AO10: 17448853 | AP10: 21553898 | AQ10: 19582443 | AR10: 18377509 | AS10: 17842319 | AT10: 15617538 | AU10: 17289516 | AV10: 15877483 | AW10: 15265204 | AX10: 23162466 | AY10: 18132963 | AZ10: 14530604 | BA10: 14534261 | BB10: 180009 | BC10: 168453 | BD10: 186552 | BE10: 233512 | BF10: 195427 | BG10: 165438 | BH10: 178776 | BI10: 172668 | BJ10: 171223 | BK10: 164235 | BL10: 200018 | BM10: 192457 | BN10: 223408 | BO10: 294702 | BP10: 190815 | BQ10: 143821 | BR10: 156540 | BS10: 162342 | BT10: 155998 | BU10: 203383 | BV10: 196488 | BW10: 179477 | BX10: 178714 | BY10: 195221 | BZ10: 241149 | CA10: 219092 | CB10: 190955 | CC10: 185394 | CD10: 162277 | CE10: 179650 | CF10: 164978 | CG10: 158616 | CH10: 240674 | CI10: 188414 | CJ10: 150983 | CK10: 151021
A11: =RIGHT(B11,5) -> V3X2 | B11: SEX TONICS & STIMULANTS | V3X2 | C11: ADDYZOA | D11: CHARAK PHARMA PVT LTD | E11: ADDYZOA CAPSULE 20 | F11: 132.13 | G11: 10.837602 | H11: 11.946439 | I11: 11.564507 | J11: 12.296885 | K11: 13.049718 | L11: 987.267 | M11: 1063.121 | N11: 971.048 | O11: 994.235 | P11: 1006.264 | R11: 9851318 | S11: 8984650.1 | T11: 8524702.8 | U11: 9099665.8 | V11: 9328771.6 | W11: 8862445.8 | X11: 9900586.8 | Y11: 11292303 | Z11: 10739842 | AA11: 9979267 | AB11: 10281117 | AC11: 8800400.2 | AD11: 9663939.2 | AE11: 11600467 | AF11: 8316662.9 | AG11: 6111068.6 | AH11: 6248394.6 | AI11: 9548104.5 | AJ11: 10589524 | AK11: 10821679 | AL11: 11292195 | AM11: 13087906 | AN11: 12395556 | AO11: 13293348 | AP11: 12377123 | AQ11: 11724564 | AR11: 11907504 | AS11: 9940421.8 | AT11: 7293956.6 | AU11: 9316594.9 | AV11: 10726049 | AW11: 12906855 | AX11: 11437437 | AY11: 11025059 | AZ11: 9967358.7 | BA11: 11874259 | BB11: 85138 | BC11: 77648 | BD11: 73673 | BE11: 78642 | BF11: 80622 | BG11: 72990 | BH11: 81540 | BI11: 93002 | BJ11: 88452 | BK11: 82188 | BL11: 84674 | BM11: 72479 | BN11: 79591 | BO11: 95540 | BP11: 68495 | BQ11: 50330 | BR11: 51461 | BS11: 78637 | BT11: 87214 | BU11: 89126 | BV11: 88824 | BW11: 102949 | BX11: 97503 | BY11: 104565 | BZ11: 97358 | CA11: 92225 | CB11: 93664 | CC11: 78191 | CD11: 57374 | CE11: 73284 | CF11: 81178 | CG11: 97683 | CH11: 86562 | CI11: 83441 | CJ11: 75436 | CK11: 89868
A12: =RIGHT(B12,5) -> V3X2 | B12: SEX TONICS & STIMULANTS | V3X2 | C12: HIMCOLIN | D12: HIMALAYA DRUG COMPANY | E12: HIMCOLIN GEL 30 GM | F12: 120.31 | G12: 6.3444094 | H12: 10.231342 | I12: 12.178191 | J12: 10.320915 | K12: 9.6567242 | L12: 665.234 | M12: 1063.107 | N12: 1188.086 | O12: 938.265 | P12: 821.656 | R12: 10260724 | S12: 9748655.4 | T12: 8157204.5 | U12: 13178427 | V12: 11790328 | W12: 9385054.3 | X12: 9783510 | Y12: 8271358.3 | Z12: 8884613 | AA12: 9812280.5 | AB12: 11009297 | AC12: 11500458 | AD12: 13788500 | AE12: 12305810 | AF12: 8877330 | AG12: 6434230 | AH12: 6770170 | AI12: 7754340 | AJ12: 7034830 | AK12: 6675460 | AL12: 7338540 | AM12: 8561960 | AN12: 8043310 | AO12: 9624670 | AP12: 8775470 | AQ12: 8192470 | AR12: 7424010 | AS12: 7566897.5 | AT12: 6671670.7 | AU12: 8400284.8 | AV12: 8092050.6 | AW12: 7781049.2 | AX12: 7819789.1 | AY12: 9969488.2 | AZ12: 8014931.9 | BA12: 7859130.4 | BB12: 106616 | BC12: 94537 | BD12: 79104 | BE12: 127797 | BF12: 114336 | BG12: 91011 | BH12: 94875 | BI12: 80211 | BJ12: 86158 | BK12: 95154 | BL12: 106762 | BM12: 111525 | BN12: 125350 | BO12: 111871 | BP12: 80703 | BQ12: 58493 | BR12: 61547 | BS12: 70494 | BT12: 63953 | BU12: 60686 | BV12: 66714 | BW12: 77836 | BX12: 73121 | BY12: 87497 | BZ12: 79777 | CA12: 74477 | CB12: 67491 | CC12: 62895 | CD12: 55454 | CE12: 69822 | CF12: 67260 | CG12: 64675 | CH12: 64997 | CI12: 82865 | CJ12: 66619 | CK12: 65324
A13: =RIGHT(B13,5) -> V3X2 | B13: SEX TONICS & STIMULANTS | V3X2 | C13: SIOTONE | D13: ALBERT DAVID | E13: SIOTONE CAPSULE 10 | F13: 117.14 | G13: 8.9375234 | H13: 8.32464 | I13: 8.236171 | J13: 6.394069 | K13: 7.7516612 | L13: 865.056 | M13: 832.464 | N13: 786.66 | O13: 581.279 | P13: 665.237 | R13: 7222300 | S13: 6338900 | T13: 6818100 | U13: 7786300 | V13: 6793800 | W13: 6749500 | X13: 8159360 | Y13: 6590760 | Z13: 6938690 | AA13: 5927570 | AB13: 6614960 | AC13: 6421470 | AD13: 7158910 | AE13: 7149780 | AF13: 4779390 | AG13: 3546070 | AH13: 3964840 | AI13: 5220380 | AJ13: 5126330 | AK13: 5030300 | AL13: 5173630 | AM13: 5147230 | AN13: 5292980 | AO13: 6350850 | AP13: 6304980 | AQ13: 6652146.3 | AR13: 7400670.9 | AS13: 7217815.4 | AT13: 5598120.6 | AU13: 6044189.7 | AV13: 6243327.7 | AW13: 6273198.4 | AX13: 6037512.7 | AY13: 6308809 | AZ13: 6366324.7 | BA13: 7069516.1 | BB13: 72223 | BC13: 63389 | BD13: 68181 | BE13: 77863 | BF13: 67938 | BG13: 67495 | BH13: 74176 | BI13: 59916 | BJ13: 63079 | BK13: 53887 | BL13: 60136 | BM13: 58377 | BN13: 65081 | BO13: 64998 | BP13: 43449 | BQ13: 32237 | BR13: 36044 | BS13: 47458 | BT13: 46603 | BU13: 45730 | BV13: 47033 | BW13: 46793 | BX13: 48118 | BY13: 57735 | BZ13: 57318 | CA13: 56788 | CB13: 63178 | CC13: 61617 | CD13: 47790 | CE13: 51598 | CF13: 53298 | CG13: 53553 | CH13: 51541 | CI13: 53857 | CJ13: 54348 | CK13: 60351
A14: =RIGHT(B14,5) -> V3X2 | B14: SEX TONICS & STIMULANTS | V3X2 | C14: ENDOBLOC T | D14: CIPLA LTD. | E14: ENDOBLOC T KIT TABLET 10 | F14: 1359.6 | G14: 1.7859071 | H14: 3.8063685 | I14: 4.7201856 | J14: 6.3375272 | K14: 7.3298755 | L14: 14.996 | M14: 30.278 | N14: 36.166 | O14: 47.273 | P14: 53.912 | R14: 3625591.8 | S14: 3518734.9 | T14: 3600449 | U14: 4478760 | V14: 4274160 | W14: 4365240 | X14: 3986400 | Y14: 3486120 | Z14: 3462360 | AA14: 3626040 | AB14: 3891360 | AC14: 4886640 | AD14: 5109720 | AE14: 5252280 | AF14: 5228520 | AG14: 4778400 | AH14: 4650360 | AI14: 4884000 | AJ14: 5808211.2 | AK14: 4486680 | AL14: 5286124.8 | AM14: 5949609.6 | AN14: 5590675.2 | AO14: 6350691.6 | AP14: 5753827.2 | AQ14: 5785098 | AR14: 6561429.6 | AS14: 5781019.2 | AT14: 5500941.6 | AU14: 4810264.8 | AV14: 4738206 | AW14: 5095780.8 | AX14: 5862595.2 | AY14: 6789842.4 | AZ14: 7918310.4 | BA14: 8701440 | BB14: 2884 | BC14: 2799 | BD14: 2864 | BE14: 3393 | BF14: 3238 | BG14: 3307 | BH14: 3020 | BI14: 2641 | BJ14: 2623 | BK14: 2747 | BL14: 2948 | BM14: 3702 | BN14: 3871 | BO14: 3979 | BP14: 3961 | BQ14: 3620 | BR14: 3523 | BS14: 3700 | BT14: 4272 | BU14: 3300 | BV14: 3888 | BW14: 4376 | BX14: 4112 | BY14: 4671 | BZ14: 4232 | CA14: 4255 | CB14: 4826 | CC14: 4252 | CD14: 4046 | CE14: 3538 | CF14: 3485 | CG14: 3748 | CH14: 4312 | CI14: 4994 | CJ14: 5824 | CK14: 6400
A15: =RIGHT(B15,5) -> V3X2 | B15: SEX TONICS & STIMULANTS | V3X2 | C15: SPEMAN | D15: HIMALAYA DRUG COMPANY | E15: SPEMAN TABLET 60 | F15: 99.69 | G15: 8.9340506 | H15: 8.960424 | I15: 8.5660266 | J15: 8.0282692 | K15: 7.1490788 | L15: 1094.881 | M15: 1086.112 | N15: 996.861 | O15: 865.022 | P15: 735.431 | R15: 7738769.9 | S15: 7317798.8 | T15: 7047549 | U15: 7691852.1 | V15: 7252749.8 | W15: 7867235.2 | X15: 6652958.4 | Y15: 6434524.3 | Z15: 6328057.1 | AA15: 7365060.3 | AB15: 7567253.6 | AC15: 6396457.3 | AD15: 7698311.1 | AE15: 7884487.9 | AF15: 6227736.6 | AG15: 4205313.9 | AH15: 5070303.1 | AI15: 6114137.2 | AJ15: 6288620 | AK15: 7262382.5 | AL15: 7790100.2 | AM15: 7771723.8 | AN15: 6888451 | AO15: 7081124.6 | AP15: 6911653.5 | AQ15: 6265788.7 | AR15: 5634773.5 | AS15: 5797655.1 | AT15: 5384456.3 | AU15: 6283460.7 | AV15: 5933648.5 | AW15: 5865759.6 | AX15: 5696884.7 | AY15: 5951592.7 | AZ15: 4933259.3 | BA15: 6831855.4 | BB15: 90059 | BC15: 85160 | BD15: 82015 | BE15: 89513 | BF15: 84403 | BG15: 91554 | BH15: 77423 | BI15: 74881 | BJ15: 73642 | BK15: 85710 | BL15: 88063 | BM15: 74438 | BN15: 82947 | BO15: 84953 | BP15: 67102 | BQ15: 45311 | BR15: 54631 | BS15: 65878 | BT15: 67758 | BU15: 78250 | BV15: 83936 | BW15: 83738 | BX15: 74221 | BY15: 76297 | BZ15: 74471 | CA15: 67512 | CB15: 60713 | CC15: 62468 | CD15: 54012 | CE15: 63030 | CF15: 59521 | CG15: 58840 | CH15: 57146 | CI15: 59701 | CJ15: 49486 | CK15: 68531
A16: =RIGHT(B16,5) -> V3X2 | B16: SEX TONICS & STIMULANTS | V3X2 | C16: NANO LEO | D16: SANZYME LTD | E16: NANO LEO CAPSULE 15 | F16: 508.47 | G16: 5.1178064 | H16: 5.9034374 | I16: 6.209049 | J16: 4.4764274 | K16: 7.0084846 | L16: 127.128 | M16: 133.962 | N16: 140.897 | O16: 101.58 | P16: 139.022 | R16: 5875586.4 | S16: 5051514.8 | T16: 6255452.6 | U16: 5935078.2 | V16: 5879993.2 | W16: 5136566.1 | X16: 4550461.7 | Y16: 4709987.8 | Z16: 4553546.4 | AA16: 4154731 | AB16: 4726293 | AC16: 5261278.5 | AD16: 5548601.9 | AE16: 3877984 | AF16: 3385303.8 | AG16: 2239095.1 | AH16: 2712385.4 | AI16: 4234934.8 | AJ16: 3562897.8 | AK16: 4019001.6 | AL16: 3284388 | AM16: 3796898.9 | AN16: 3682322.1 | AO16: 4420461.1 | AP16: 3924255.4 | AQ16: 5960793.8 | AR16: 5964861.6 | AS16: 5625712.1 | AT16: 4475552.9 | AU16: 4971819.7 | AV16: 5371985.5 | AW16: 5848930.4 | AX16: 6052318.4 | AY16: 6440281 | AZ16: 6966547.5 | BA16: 8481788.1 | BB16: 13333 | BC16: 11463 | BD16: 14195 | BE16: 13468 | BF16: 13343 | BG16: 11656 | BH16: 10326 | BI16: 10688 | BJ16: 10333 | BK16: 9428 | BL16: 10725 | BM16: 11939 | BN16: 12591 | BO16: 8800 | BP16: 7682 | BQ16: 5081 | BR16: 6155 | BS16: 9610 | BT16: 8085 | BU16: 9120 | BV16: 7453 | BW16: 8616 | BX16: 8356 | BY16: 10031 | BZ16: 8905 | CA16: 11723 | CB16: 11731 | CC16: 11064 | CD16: 8802 | CE16: 9778 | CF16: 10565 | CG16: 11503 | CH16: 11903 | CI16: 12666 | CJ16: 13701 | CK16: 16681
A17: =RIGHT(B17,5) -> V3X2 | B17: SEX TONICS & STIMULANTS | V3X2 | C17: VIRILEX | D17: TTK HEALTHCARE LTD | E17: VIRILEX TABLET 20 | F17: 375 | G17: 5.6440445 | H17: 5.5517663 | I17: 5.3500679 | J17: 5.3306099 | K17: 6.2840625 | L17: 197.686 | M17: 178.68 | N17: 158.121 | O17: 143.436 | P17: 167.575 | R17: 4921335.7 | S17: 5233439 | T17: 4804603 | U17: 4441662.9 | V17: 4946637.8 | W17: 3621206.6 | X17: 3985853.8 | Y17: 3870109 | Z17: 4199589 | AA17: 3916202.1 | AB17: 4778654.3 | AC17: 4781385.7 | AD17: 4906349.1 | AE17: 4208250 | AF17: 3529125 | AG17: 2508375 | AH17: 3630750 | AI17: 4341375 | AJ17: 4280625 | AK17: 4537875 | AL17: 4610625 | AM17: 5217000 | AN17: 5371125 | AO17: 6164625 | AP17: 7264500 | AQ17: 7221750 | AR17: 7165875 | AS17: 4787250 | AT17: 4168500 | AU17: 4416750 | AV17: 4813125 | AW17: 4403625 | AX17: 4336500 | AY17: 4364250 | AZ17: 4184250 | BA17: 5714250 | BB17: 15839 | BC17: 15328 | BD17: 14072 | BE17: 13009 | BF17: 14488 | BG17: 10606 | BH17: 11674 | BI17: 11335 | BJ17: 12300 | BK17: 11470 | BL17: 13996 | BM17: 14004 | BN17: 14370 | BO17: 11222 | BP17: 9411 | BQ17: 6689 | BR17: 9682 | BS17: 11577 | BT17: 11415 | BU17: 12101 | BV17: 12295 | BW17: 13912 | BX17: 14323 | BY17: 16439 | BZ17: 19372 | CA17: 19258 | CB17: 19109 | CC17: 12766 | CD17: 11116 | CE17: 11778 | CF17: 12835 | CG17: 11743 | CH17: 11564 | CI17: 11638 | CJ17: 11158 | CK17: 15238
A18: =RIGHT(B18,5) -> V3X2 | B18: SEX TONICS & STIMULANTS | V3X2 | C18: ERACT X | D18: ZYDUS CADILA - ZHL | E18: ERACT X SACHET 10 GM | F18: 62.24 | G18: 0 | H18: 1.5142289 | I18: 5.6595108 | J18: 5.6511347 | K18: 6.0488706 | L18: 0 | M18: 280.933 | N18: 1050.002 | O18: 1048.448 | P18: 991.467 | R18: 4380021.8 | S18: 4065677 | T18: 4476071.6 | U18: 4905169.5 | V18: 4647581.4 | W18: 4101520.5 | X18: 4166038.8 | Y18: 4909319.8 | Z18: 5013131.2 | AA18: 4723796 | AB18: 5433820.7 | AC18: 5772959.5 | AD18: 5735391.2 | AE18: 7812805 | AF18: 5885664.4 | AG18: 2602399.8 | AH18: 3157785.4 | AI18: 4517736.3 | AJ18: 4064545.1 | AK18: 4517197.3 | AL18: 4672105.9 | AM18: 4820223.1 | AN18: 4108904.8 | AO18: 4616588.9 | AP18: 6455495.2 | AQ18: 6661705.8 | AR18: 6421403.5 | AS18: 4985340.4 | AT18: 3714669.9 | AU18: 3950061.6 | AV18: 4610490.2 | AW18: 4319518.2 | AX18: 4826712 | AY18: 4836234.7 | AZ18: 4384372.3 | BA18: 5322702.6 | BB18: 81262 | BC18: 75430 | BD18: 83044 | BE18: 91005 | BF18: 86226 | BG18: 76095 | BH18: 77292 | BI18: 91082 | BJ18: 93008 | BK18: 87640 | BL18: 100813 | BM18: 107105 | BN18: 106408 | BO18: 144950 | BP18: 109196 | BQ18: 48282 | BR18: 58586 | BS18: 83817 | BT18: 75409 | BU18: 83807 | BV18: 86681 | BW18: 89429 | BX18: 76232 | BY18: 85651 | BZ18: 108880 | CA18: 112358 | CB18: 108305 | CC18: 84084 | CD18: 59683 | CE18: 63465 | CF18: 74076 | CG18: 69401 | CH18: 77550 | CI18: 77703 | CJ18: 70443 | CK18: 85519
A19: =RIGHT(B19,5) -> V3X2 | B19: SEX TONICS & STIMULANTS | V3X2 | C19: NEO | D19: CHARAK PHARMA PVT LTD | E19: NEO TABLET 75 | F19: 91.43 | G19: 4.5704535 | H19: 4.903752 | I19: 5.1904837 | J19: 4.880152 | K19: 5.2528079 | L19: 603.185 | M19: 625.205 | N19: 627.915 | O19: 574.183 | P19: 590.353 | R19: 5286800 | S19: 4567440 | T19: 4891200 | U19: 4315040 | V19: 4447899 | W19: 4286905.1 | X19: 3917377.8 | Y19: 4517016.8 | Z19: 4552165.7 | AA19: 4004027.9 | AB19: 3586961 | AC19: 3532003.9 | AD19: 3612079.4 | AE19: 4592624.9 | AF19: 3200828.5 | AG19: 2308703.1 | AH19: 2926043.1 | AI19: 4096999.7 | AJ19: 4202783.7 | AK19: 4275778.8 | AL19: 4386283 | AM19: 5265680.6 | AN19: 4639008 | AO19: 5294707.2 | AP19: 5562768 | AQ19: 5079098.7 | AR19: 4682938 | AS19: 4057111.2 | AT19: 3814354 | AU19: 3854945.4 | AV19: 3900193.3 | AW19: 4682235.1 | AX19: 4317416 | AY19: 4222603.1 | AZ19: 3776424.7 | BA19: 4577991.5 | BB19: 66085 | BC19: 57093 | BD19: 61140 | BE19: 53938 | BF19: 52769 | BG19: 50859 | BH19: 46475 | BI19: 53589 | BJ19: 54006 | BK19: 47503 | BL19: 42555 | BM19: 41903 | BN19: 42853 | BO19: 54486 | BP19: 37974 | BQ19: 27390 | BR19: 34714 | BS19: 48606 | BT19: 49861 | BU19: 50727 | BV19: 52038 | BW19: 62471 | BX19: 52800 | BY19: 60263 | BZ19: 63314 | CA19: 57809 | CB19: 53300 | CC19: 46177 | CD19: 43414 | CE19: 43876 | CF19: 44391 | CG19: 53292 | CH19: 47221 | CI19: 46184 | CJ19: 41304 | CK19: 50071
A20: =RIGHT(B20,5) -> V3X2 | B20: SEX TONICS & STIMULANTS | V3X2 | C20: SEMENTO | D20: AIMIL PHARMACEUTICAL (INDIA) | E20: SEMENTO CAPSULE 20 | F20: 178.46 | G20: 0 | H20: 0 | I20: 1.5792279 | J20: 4.017918 | K20: 4.1960721 | L20: 0 | M20: 0 | N20: 97.345 | O20: 247.668 | P20: 239.452 | R20: 0 | S20: 0 | T20: 0 | U20: 0 | V20: 104151.66 | W20: 411253.05 | X20: 433154.1 | Y20: 3380548.7 | Z20: 3616755.6 | AA20: 2903917 | AB20: 1879759 | AC20: 3062740.2 | AD20: 3215723.1 | AE20: 3284508.6 | AF20: 3067282.6 | AG20: 2297825.7 | AH20: 2638508.7 | AI20: 3084479 | AJ20: 3064038 | AK20: 3226916.9 | AL20: 3587878.7 | AM20: 3953869.6 | AN20: 3915421 | AO20: 4842727.7 | AP20: 4276220.6 | AQ20: 3439276 | AR20: 3752656.9 | AS20: 3252612 | AT20: 2460071.1 | AU20: 3247615.1 | AV20: 3209246.2 | AW20: 3161240.4 | AX20: 3822613.2 | AY20: 3363078.7 | AZ20: 3523157.3 | BA20: 4452933.9 | BB20: 0 | BC20: 0 | BD20: 0 | BE20: 0 | BF20: 642 | BG20: 2535 | BH20: 2670 | BI20: 20838 | BJ20: 22294 | BK20: 17900 | BL20: 11587 | BM20: 18879 | BN20: 19822 | BO20: 20246 | BP20: 18907 | BQ20: 14164 | BR20: 16264 | BS20: 19013 | BT20: 18887 | BU20: 19891 | BV20: 22116 | BW20: 24372 | BX20: 24135 | BY20: 29851 | BZ20: 26359 | CA20: 21200 | CB20: 21028 | CC20: 18226 | CD20: 13785 | CE20: 18198 | CF20: 17983 | CG20: 17714 | CH20: 21420 | CI20: 18845 | CJ20: 19742 | CK20: 24952
A21: =RIGHT(B21,5) -> V3X2 | B21: SEX TONICS & STIMULANTS | V3X2 | C21: SHILAJIT | D21: DABUR INDIA LTD. | E21: SHILAJIT CAPSULE 10 | F21: 51.28 | G21: 0.44898127 | H21: 0.23441662 | I21: 0.052577847 | J21: 0.006796755 | K21: 0.004493347 | L21: 86.763 | M21: 46.205 | N21: 10.504 | O21: 1.317 | P21: 0.875 | R21: 157900 | S21: 106250 | T21: 123200 | U21: 106600 | V21: 10800 | W21: 3404.94 | X21: 2597.5 | Y21: 2493.6 | Z21: 1792.7 | AA21: 1382.94 | AB21: 4601.7 | AC21: 4755.09 | AD21: 5677.65 | AE21: 5423.25 | AF21: 5371.6 | AG21: 6249.65 | AH21: 5423.25 | AI21: 6714.5 | AJ21: 4286.95 | AK21: 8005.75 | AL21: 7747.5 | AM21: 7747.5 | AN21: 4545.2 | AO21: 774.75 | AP21: 0 | AQ21: 0 | AR21: 103.3 | AS21: 7799.15 | AT21: 7799.15 | AU21: 7774.8 | AV21: 3938.55 | AW21: 1790.25 | AX21: 1687.95 | AY21: 4092 | AZ21: 4717.76 | BA21: 5230.56 | BB21: 3158 | BC21: 2125 | BD21: 2464 | BE21: 2132 | BF21: 216 | BG21: 66 | BH21: 50 | BI21: 48 | BJ21: 35 | BK21: 27 | BL21: 90 | BM21: 93 | BN21: 111 | BO21: 105 | BP21: 104 | BQ21: 121 | BR21: 105 | BS21: 130 | BT21: 83 | BU21: 155 | BV21: 150 | BW21: 150 | BX21: 88 | BY21: 15 | BZ21: 0 | CA21: 0 | CB21: 2 | CC21: 151 | CD21: 151 | CE21: 152 | CF21: 77 | CG21: 35 | CH21: 33 | CI21: 80 | CJ21: 92 | CK21: 102
A22: =RIGHT(B22,5) -> V3X2 | B22: SEX TONICS & STIMULANTS | V3X2 | C22: =C21 -> SHILAJIT | D22: =D21 -> DABUR INDIA LTD. | E22: SHILAJIT CAPSULE 100 | F22: 372.03 | G22: 0.38717641 | H22: 0.308342 | I22: 0.16010693 | J22: 0.11247338 | K22: 0.094160419 | L22: 9.712 | M22: 8.072 | N22: 4.187 | O22: 2.94 | P22: 2.499 | R22: 290302.32 | S22: 116273.92 | T22: 96393 | U22: 64256.64 | V22: 126600.88 | W22: 95620 | X22: 123923.52 | Y22: 181295.52 | Z22: 206156.72 | AA22: 127748.32 | AB22: 102122.16 | AC22: 70376.32 | AD22: 86058 | AE22: 64256.64 | AF22: 75348.56 | AG22: 86822.96 | AH22: 95667.5 | AI22: 96384.96 | AJ22: 93325.12 | AK22: 84570.07 | AL22: 83804.73 | AM22: 84570.07 | AN22: 140057.22 | AO22: 133868 | AP22: 115891.44 | AQ22: 114744 | AR22: 100592.24 | AS22: 102555.56 | AT22: 75894.12 | AU22: 86310.96 | AV22: 77382.24 | AW22: 75894.12 | AX22: 71801.79 | AY22: 70313.67 | AZ22: 22693.83 | BA22: 27530.22 | BB22: 759 | BC22: 304 | BD22: 253 | BE22: 168 | BF22: 331 | BG22: 250 | BH22: 324 | BI22: 474 | BJ22: 539 | BK22: 334 | BL22: 267 | BM22: 184 | BN22: 225 | BO22: 168 | BP22: 197 | BQ22: 227 | BR22: 250 | BS22: 252 | BT22: 244 | BU22: 221 | BV22: 219 | BW22: 221 | BX22: 366 | BY22: 350 | BZ22: 303 | CA22: 300 | CB22: 263 | CC22: 268 | CD22: 204 | CE22: 232 | CF22: 208 | CG22: 204 | CH22: 193 | CI22: 189 | CJ22: 61 | CK22: 74
A23: =RIGHT(B23,5) -> V3X2 | B23: SEX TONICS & STIMULANTS | V3X2 | C23: =C22 -> SHILAJIT | D23: =D22 -> DABUR INDIA LTD. | E23: SHILAJIT CAPSULE 30 | F23: 149.38 | G23: 0.75483107 | H23: 0.3950917 | I23: 0.34328554 | J23: 0.24437622 | K23: 0.28762404 | L23: 47.16 | M23: 26.395 | N23: 23.009 | O23: 16.287 | P23: 19.203 | R23: 297594.15 | S23: 358753.85 | T23: 354278.75 | U23: 284168.85 | V23: 373670.85 | W23: 276412.01 | X23: 202722.03 | Y23: 262363.92 | Z23: 239679.44 | AA23: 205503.48 | AB23: 272959.96 | AC23: 304748.08 | AD23: 274900.08 | AE23: 151627.84 | AF23: 156702 | AG23: 181625.08 | AH23: 164910.2 | AI23: 165131.19 | AJ23: 196307.72 | AK23: 203764.95 | AL23: 206249.68 | AM23: 230471.96 | AN23: 257707.2 | AO23: 254364.3 | AP23: 283705.24 | AQ23: 302405.71 | AR23: 178938.76 | AS23: 313011.6 | AT23: 316687.91 | AU23: 217937.37 | AV23: 181548.8 | AW23: 193642.1 | AX23: 189712.6 | AY23: 200019.82 | AZ23: 245879.48 | BA23: 252750.96 | BB23: 1995 | BC23: 2405 | BD23: 2375 | BE23: 1905 | BF23: 2505 | BG23: 1853 | BH23: 1359 | BI23: 1758 | BJ23: 1606 | BK23: 1377 | BL23: 1829 | BM23: 2042 | BN23: 1842 | BO23: 1016 | BP23: 1050 | BQ23: 1217 | BR23: 1105 | BS23: 1107 | BT23: 1316 | BU23: 1341 | BV23: 1382 | BW23: 1541 | BX23: 1696 | BY23: 1674 | BZ23: 1901 | CA23: 1997 | CB23: 1199 | CC23: 2062 | CD23: 2123 | CE23: 1461 | CF23: 1216 | CG23: 1297 | CH23: 1270 | CI23: 1339 | CJ23: 1646 | CK23: 1692
A24: =RIGHT(B24,5) -> V3X2 | B24: SEX TONICS & STIMULANTS | V3X2 | C24: =C23 -> SHILAJIT | D24: =D23 -> DABUR INDIA LTD. | E24: SHILAJIT CAPSULE 50 | F24: 200.94 | G24: 0.054890318 | H24: 0 | I24: 0 | J24: 0 | K24: 0 | L24: 2.887 | M24: 0 | N24: 0 | O24: 0 | P24: 0 | R24: 0 | S24: 0 | T24: 0 | U24: 0 | V24: 0 | W24: 0 | X24: 0 | Y24: 0 | Z24: 0 | AA24: 0 | AB24: 0 | AC24: 0 | AD24: 0 | AE24: 0 | AF24: 0 | AG24: 0 | AH24: 0 | AI24: 0 | AJ24: 0 | AK24: 0 | AL24: 0 | AM24: 0 | AN24: 0 | AO24: 0 | AP24: 0 | AQ24: 0 | AR24: 0 | AS24: 0 | AT24: 0 | AU24: 0 | AV24: 0 | AW24: 0 | AX24: 0 | AY24: 0 | AZ24: 0 | BA24: 0 | BB24: 0 | BC24: 0 | BD24: 0 | BE24: 0 | BF24: 0 | BG24: 0 | BH24: 0 | BI24: 0 | BJ24: 0 | BK24: 0 | BL24: 0 | BM24: 0 | BN24: 0 | BO24: 0 | BP24: 0 | BQ24: 0 | BR24: 0 | BS24: 0 | BT24: 0 | BU24: 0 | BV24: 0 | BW24: 0 | BX24: 0 | BY24: 0 | BZ24: 0 | CA24: 0 | CB24: 0 | CC24: 0 | CD24: 0 | CE24: 0 | CF24: 0 | CG24: 0 | CH24: 0 | CI24: 0 | CJ24: 0 | CK24: 0
A25: =RIGHT(B25,5) -> V3X2 | B25: SEX TONICS & STIMULANTS | V3X2 | C25: =C24 -> SHILAJIT | D25: =D24 -> DABUR INDIA LTD. | E25: SHILAJIT GOLD CAPSULE 10 | F25: 182.29 | G25: 7.880662 | H25: 5.0835817 | I25: 4.3843778 | J25: 2.3380263 | K25: 2.7838706 | L25: 495.706 | M25: 331.519 | N25: 274.075 | O25: 139.223 | P25: 155.18 | R25: 7356380.4 | S25: 6155005.7 | T25: 4816536.7 | U25: 4216009.3 | V25: 3889670.5 | W25: 2958965.1 | X25: 2557920.3 | Y25: 2105525.1 | Z25: 2075450.8 | AA25: 2287251.1 | AB25: 2678537.7 | AC25: 2746524.9 | AD25: 2964917 | AE25: 2476302.3 | AF25: 2266779.1 | AG25: 2102434.4 | AH25: 2352148.2 | AI25: 1567550.8 | AJ25: 1415758.5 | AK25: 1512728.7 | AL25: 1534522.7 | AM25: 1743130.2 | AN25: 1521859.1 | AO25: 1922132.2 | AP25: 1969706.3 | AQ25: 1517067.4 | AR25: 1721396.7 | AS25: 1677758.5 | AT25: 1953419.6 | AU25: 2136074.2 | AV25: 2328754.8 | AW25: 2542945.5 | AX25: 2355916 | AY25: 2645027.9 | AZ25: 3270647.2 | BA25: 3719992 | BB25: 45986 | BC25: 38476 | BD25: 30109 | BE25: 26355 | BF25: 24315 | BG25: 18497 | BH25: 15990 | BI25: 13162 | BJ25: 12974 | BK25: 14298 | BL25: 16744 | BM25: 17169 | BN25: 18113 | BO25: 15128 | BP25: 13848 | BQ25: 12844 | BR25: 13744 | BS25: 9160 | BT25: 8273 | BU25: 8835 | BV25: 8967 | BW25: 10186 | BX25: 8893 | BY25: 11232 | BZ25: 11510 | CA25: 8865 | CB25: 10059 | CC25: 9804 | CD25: 10716 | CE25: 11718 | CF25: 12775 | CG25: 13950 | CH25: 12924 | CI25: 14510 | CJ25: 17942 | CK25: 20407
A26: =RIGHT(B26,5) -> V3X2 | B26: SEX TONICS & STIMULANTS | V3X2 | C26: =C25 -> SHILAJIT | D26: =D25 -> DABUR INDIA LTD. | E26: SHILAJIT GOLD CAPSULE 20 | F26: 331.1 | G26: 2.0594919 | H26: 0.99147 | I26: 1.0453589 | J26: 0.46088273 | K26: 0.58966097 | L26: 68.329 | M26: 34.014 | N26: 34.254 | O26: 14.59 | P26: 18.111 | R26: 1746468.8 | S26: 1558148.1 | T26: 1440028 | U26: 1090245.8 | V26: 969989.16 | W26: 947402.88 | X26: 885894.24 | Y26: 864234.98 | Z26: 126294.84 | AA26: 195238.4 | AB26: 231540.54 | AC26: 398103.3 | AD26: 431275.86 | AE26: 442413.9 | AF26: 380194.56 | AG26: 312660 | AH26: 268574.94 | AI26: 386447.76 | AJ26: 475555.86 | AK26: 391951 | AL26: 399925 | AM26: 326999.12 | AN26: 408563.38 | AO26: 384265.96 | AP26: 465541.8 | AQ26: 426506.68 | AR26: 388087.22 | AS26: 472551.38 | AT26: 472260.96 | AU26: 447624.04 | AV26: 505536.8 | AW26: 490044.72 | AX26: 476990.25 | AY26: 541626.45 | AZ26: 593993.4 | BA26: 615846 | BB26: 5722 | BC26: 5105 | BD26: 4718 | BE26: 3572 | BF26: 3178 | BG26: 3104 | BH26: 2904 | BI26: 2833 | BJ26: 414 | BK26: 640 | BL26: 759 | BM26: 1305 | BN26: 1413 | BO26: 1415 | BP26: 1216 | BQ26: 1000 | BR26: 859 | BS26: 1236 | BT26: 1521 | BU26: 1225 | BV26: 1250 | BW26: 1022 | BX26: 1277 | BY26: 1156 | BZ26: 1455 | CA26: 1333 | CB26: 1213 | CC26: 1477 | CD26: 1476 | CE26: 1399 | CF26: 1580 | CG26: 1464 | CH26: 1425 | CI26: 1635 | CJ26: 1794 | CK26: 1860
A27: =RIGHT(B27,5) -> V3X2 | B27: SEX TONICS & STIMULANTS | V3X2 | C27: NANO LEO TOTAL | D27: SANZYME LTD | E27: NANO LEO TOTAL CAPSULE 10 | F27: 50.85 | G27: 1.1737272 | H27: 0.5051141 | I27: 0.49240235 | J27: 0.091727988 | K27: 0.000544095 | L27: 27.258 | M27: 9.934 | N27: 9.684 | O27: 1.804 | P27: 0.107 | R27: 626943.51 | S27: 866941.35 | T27: 710841.06 | U27: 793213.2 | V27: 447962.07 | W27: 270506.04 | X27: 254235 | Y27: 261862.05 | Z27: 173388.27 | AA27: 141354.66 | AB27: 182540.73 | AC27: 194235.54 | AD27: 221184.45 | AE27: 208981.17 | AF27: 170337.45 | AG27: 167795.1 | AH27: 10169.4 | AI27: 9660.93 | AJ27: 13728.69 | AK27: 27457.38 | AL27: 16779.51 | AM27: 35084.43 | AN27: 19321.86 | AO27: 16779.51 | AP27: 2695.05 | AQ27: 2745.9 | AR27: 0 | AS27: 0 | AT27: 0 | AU27: 0 | AV27: 0 | AW27: 0 | AX27: 0 | AY27: 0 | AZ27: 0 | BA27: 0 | BB27: 1233 | BC27: 1705 | BD27: 1398 | BE27: 1560 | BF27: 881 | BG27: 532 | BH27: 500 | BI27: 515 | BJ27: 341 | BK27: 278 | BL27: 359 | BM27: 382 | BN27: 435 | BO27: 411 | BP27: 335 | BQ27: 330 | BR27: 20 | BS27: 19 | BT27: 27 | BU27: 54 | BV27: 33 | BW27: 69 | BX27: 38 | BY27: 33 | BZ27: 53 | CA27: 54 | CB27: 0 | CC27: 0 | CD27: 0 | CE27: 0 | CF27: 0 | CG27: 0 | CH27: 0 | CI27: 0 | CJ27: 0 | CK27: 0
